<mujoco model="Flappy_v8">
<!-- This version is for Initial RL. Propellers were added as control input. Mass property,
    thrust/torque from the motor may not be correct. Use built in aerodynamics.
    Compare with v5, this version improve modify the orientation setting to align IMU with world frame.
    Please use IMU sensor of orientation and position
    -->
  <compiler angle="radian" meshdir="meshes_v7/" balanceinertia="true" />
  <!-- <statistic meansize="0.0652069" extent="0.541984" center="0.0122683 -0.0367867 0.0356997"/> -->
  <!-- <option impratio="1" timestep="2e-5" gravity="0 0 -9.81" integrator="implicitfast"  density="1.225" viscosity="1.789e-5" wind="-16.5 0 0">-->
  <!-- <option impratio="1" timestep="2e-5" gravity="0 0 -9.81"  integrator="implicitfast" density="1.225" viscosity="1.789e-5"> Uncomment this to enable aerodynamics -->
  <option impratio="1" timestep="2e-5" gravity="0 0 -9.81"  integrator="implicitfast" > <!-- Uncomment this to disable aerodynamics -->
  <!-- <flag contact="disable"/>-->
  </option>
   <!-- < density="1.225" viscosity="1.789e-5" integrator="Euler"/> -->
  <visual>
    <global offwidth="3000" offheight="3000"/>
  </visual>
  <asset>
    <texture fileback="images/sunny-back.png" filedown="images/sunny-down.png" filefront="images/sunny-front.png" fileleft="images/sunny-left.png" fileright="images/sunny-right.png" fileup="images/sunny-up.png" type="skybox"/>
		<texture builtin="flat" height="1278" mark="cross" markrgb="1 1 1" name="texgeom" random="0.01" rgb1="0.8627450980392157 0.8901960784313725 0.9137254901960784" rgb2="0.9058823529411765 0.9215686274509803 0.9647058823529412" type="cube" width="127"/>
		<texture builtin="checker" height="100" name="texplane" rgb1="0.8235294117647058 0.8117647058823529 0.9450980392156862" rgb2="0.43137254901960786 0.6392156862745098 0.9019607843137255" type="2d" width="100"/>
		<material name="MatPlane" reflectance="0.5" shininess="1" specular="1" texrepeat="60 60" texture="texplane"/>
		<material name="geom" texture="texgeom" texuniform="true"/>

    <mesh name="Base" file="Base.STL"/>
<!--    <mesh name="Base" file="Base_no_prop.STL"/>-->
    <mesh name="L1" file="L1.STL"/>
    <mesh name="L2" file="L2.STL"/>
    <mesh name="L1R" file="L1R.STL"/>
    <mesh name="L2R" file="L2R.STL"/>
    <mesh name="L3" file="L3.STL"/>
    <mesh name="L7" file="L7.STL"/>
    <mesh name="L6" file="L6.STL"/>
    <mesh name="L5" file="L5.STL"/>
    <mesh name="L4" file="L4.STL"/>
    <mesh name="L3R" file="L3R.STL"/>
    <mesh name="L7R" file="L7R.STL"/>
    <mesh name="L6R" file="L6R.STL"/>
    <mesh name="L5R" file="L5R.STL"/>
    <mesh name="L4R" file="L4R.STL"/>
    <mesh name="Proximal_L" file="Proximal_L.STL"/>
    <mesh name="Proximal_R" file="Proximal_R.STL"/>
    <mesh name="Distal_L" file="Distal_L.STL"/>
    <mesh name="Distal_R" file="Distal_R.STL"/>
  </asset>

  <default>
    <geom contype="0" conaffinity="0" condim="1" solref="0.001 1"/>
    <equality solref="1e-10 1"/>
    <default class="visual">
      <geom group="2" type="mesh" contype="0" conaffinity="0" rgba="1 1 1 1" density="0" />
    </default>
    <default class="collision">
<!--      <geom contype="1" group="3" type="mesh" density="0" />-->
      <geom contype="1" group="3" density="0" />
    </default>
    <default class="aerodynamics">
      <geom group="2" type="mesh" contype="0" conaffinity="0" rgba="1 1 1 1" density="0" fluidshape="ellipsoid"/>
    </default>
  </default>

  <worldbody>
    <light cutoff="100" diffuse="1 1 1" dir="0 0 -1.3" directional="true" exponent="1" pos="0 0 1.3" specular="0.1 0.1 0.1"/>
		<geom conaffinity="1" condim="3" material="MatPlane" name="floor" pos="0 0 0" rgba="0.8 0.9 0.8 1" size="5 5 1" type="plane"/>
    
    <body name='Base' pos='0 0 2' quat="1 0 0 0">
      <freejoint/>
      <site name="motor1" type="cylinder" pos="0.148 .0 .0" size=".01 0.0025" quat="1 0 0 0" rgba=".3 .8 .3 1"/> Front
      <site name="motor2" type="cylinder" pos="-0.175 .0 .0" size=".01 0.0025" quat="1 0 0 0" rgba=".3 .8 .3 1"/> Back
      <site name="motor3" type="cylinder" pos="-0.0135 -0.236 .0" size=".01 .0025" quat="1 0 0 0" rgba=".3 .8 .3 1"/> Right
      <site name="motor4" type="cylinder" pos="-0.0135 0.236 .0" size=".01 .0025" quat="1 0 0 0" rgba=".3 .8 .3 1"/> Left

      <site name="motor5" type="cylinder" pos="-0.02309409 -0.28340624 0.00202624" size=".01 .0025" quat="0.7071068 0 0.7071068 0" rgba=".3 .8 .3 1"/> Left
      <site name="motor6" type="cylinder" pos="-0.00397818 0.28319645 0.00210978" size=".01 .0025" quat="0.7071068 0 0.7071068 0" rgba=".3 .8 .3 1"/> Right

      <geom class="collision" mesh="Base"/>
      <geom class="visual" mesh="Base"/>
<!--      <inertial pos="-0.015 0 0" quat="1 0 0 0" mass="0.045" diaginertia="2.209e-04 9.853e-05 2.208e-04"/> (include perception )Without prop-->
      <inertial pos="-0.015 0 0" quat="1 0 0 0" mass="0.095" diaginertia="1.905e-03	6.872e-04 2.261e-03"/> With guard (prop)
      <body name="L1" pos="0.0045 -0.01 -0.009798" quat="0.707105 0 0.707108 0">
        <inertial pos="0.0023972 6.0277e-09 0.0024639" quat="0 0.656907 0 0.753971" mass="0.00016152" diaginertia="2.05455e-09 1.8305e-09 5.80302e-10"/>
        <joint name="J1" type='hinge' pos="0 0 0" axis="0 0 -1" damping="0.1"/>
        <geom class="collision" mesh="L1"/>
        <geom class="visual" mesh="L1"/>
        <body name="L2" pos="0.0075 0 -0.0003" quat="0.333342 0 0 0.942806">
          <inertial pos="0.0166046 0.000296703 0.0005" quat="0.0166331 0.706911 -0.0166331 0.706911" mass="0.000195528" diaginertia="2.88378e-08 2.85892e-08 2.81176e-10"/>
          <joint name="J2" type='hinge' pos="0 0 0" axis="0 0 1" damping="0.1"/>
          <geom class="collision" mesh="L2"/>
          <geom class="visual" mesh="L2"/>
          <body name="L4" pos="0.0040958 0.0028679 0.001" quat="0.961311 0 0 0.275467">
            <inertial pos="0.0195927 0.00283964 0.0005" quat="-0.0252401 0.706656 0.0252401 0.706656" mass="0.000187735" diaginertia="2.89369e-08 2.80109e-08 9.57333e-10"/>
            <joint name="J3" type='hinge' pos="0 0 0" axis="0 0 1" damping="0.1"/>
            <geom class="collision" mesh="L4"/>
            <geom class="visual" mesh="L4"/>
            <body name="L5" pos="0.036 0 0" quat="0.850611 0 0 -0.525795">
              <inertial pos="0.0388557 0.00585307 -0.0005" quat="-0.041434 0.705892 0.041434 0.705892" mass="0.000551493" diaginertia="4.88071e-07 4.68887e-07 1.92764e-08"/>
              <joint name="J7" type='hinge' pos="0 0 0" axis="0 0 1" damping="0.1"/>
              <geom class="collision" mesh="L5"/>
              <geom class="visual" mesh="L5"/>
              <body name="L6" pos="0.091031 0 0" quat="0.833767 0 0 -0.552116">
              <inertial pos="0.0183924 -0.000169189 0.0005" quat="0.00123631 0.707106 -0.00123631 0.707106" mass="0.00017604" diaginertia="2.69855e-08 2.68812e-08 1.3361e-10"/>
                <joint name="J9" type='hinge' pos="0 0 0" axis="0 0 1" damping="0.1"/>
                <geom class="collision" mesh="L6"/>
                <geom class="visual" mesh="L6"/>
              </body>
            </body>
          </body>
        </body>
      </body>

      <body name="L3" pos="0.0052 0.020673 0.0075244" quat="0.372893 0.60079 0.372898 0.60079">
        <inertial pos="0.0243413 -0.00482289 -0.0243401" quat="0.795566 -0.0119647 -0.00383338 0.605736" mass="0.00170505" diaginertia="4.01765e-06 3.70297e-06 3.24993e-07"/>
        <joint name="J5" type='hinge' pos="0 0 0" axis="0 0 1" damping="0.1"/>
        <geom class="collision" mesh="L3"/>
        <geom class="visual" mesh="L3"/>
        <geom class="aerodynamics" mesh="Proximal_L"/>
        <body name="L7" pos="0.074121 -0.030565 -0.001" quat="0.932157 0 0 -0.362054">
          <inertial pos="0.0175244 -0.0044015 0.000591145" quat="0.694089 0.156825 0.157693 0.684675" mass="0.00371107" diaginertia="1.26925e-05 9.98807e-06 2.75403e-06"/>
          <joint name="J6" type='hinge' pos="-0.035 0 0.001" axis="0 0 1" damping="0.1"/>
          <geom class="collision" mesh="L7"/>
          <geom class="visual" mesh="L7"/>
          <geom class="aerodynamics" mesh="Distal_L"/>
        </body>
      </body>

<!--      <body name="L1R" pos="-0.0015 0.01 -0.009798" quat="-2.59734e-06 0.707105 -2.59735e-06 -0.707108">-->
      <body name="L1R" pos="-0.0015 0.01 -0.009798" quat="0 0.707108 0 -0.707108">
        <inertial pos="0.00010561 0 0.001" quat="0 0.707107 0 0.707107" mass="0.00044182" diaginertia="2.9266e-08 1.4957e-08 1.4604e-08"/>
        <joint name="J1R" pos="0 0 0" axis="0 0 -1" damping="0.1"/>
        <geom class="collision" mesh="L1R"/>
        <geom class="visual" mesh="L1R"/>
        <body name="L2R" pos="0.0075 0 0.0017" quat="0.333342 0 0 0.942806">
          <inertial pos="0.016605 0.0002967 0.0002" quat="0.0166326 0.706911 -0.0166326 0.706911" mass="0.00019553" diaginertia="2.8838e-08 2.85896e-08 2.81174e-10"/>
          <joint name="J2R" pos="0 0 0" axis="0 0 1" damping="0.1"/>
          <geom class="collision" mesh="L2R"/>
          <geom class="visual" mesh="L2R"/>
          <body name="L4R" pos="0.0040958 0.0028679 0.001" quat="0.961311 0 0 0.275467">
            <inertial pos="0.0195927 0.00283964 0.0005" quat="-0.0252401 0.706656 0.0252401 0.706656" mass="0.000187735" diaginertia="2.89369e-08 2.80109e-08 9.57333e-10"/>
            <joint name="J3R" pos="0 0 0" axis="0 0 1" damping="0.1"/>
            <geom class="collision" mesh="L4R"/>
            <geom class="visual" mesh="L4R"/>
            <body name="L5R" pos="0.036 0 0" quat="0.850611 0 0 -0.525795">
              <inertial pos="0.0388557 0.00585307 -0.0005" quat="-0.041434 0.705892 0.041434 0.705892" mass="0.000551493" diaginertia="4.88071e-07 4.68887e-07 1.92764e-08"/>
              <joint name="J7R" pos="0 0 0" axis="0 0 1" damping="0.1"/>
              <geom class="collision" mesh="L5R"/>
              <geom class="visual" mesh="L5R"/>
              <body name="L6R" pos="0.091031 0 0" quat="0.833767 0 0 -0.552116">
                <inertial pos="0.0183924 -0.000169189 0.0005" quat="0.00123631 0.707106 -0.00123631 0.707106" mass="0.00017604" diaginertia="2.69855e-08 2.68812e-08 1.3361e-10"/>
                <joint name="J9R" pos="0 0 0" axis="0 0 1" damping="0.1"/>
                <geom class="collision" mesh="L6R"/>
                <geom class="visual" mesh="L6R"/>
              </body>
            </body>
          </body>
        </body>
      </body>

      <body name="L3R" pos="-0.0042 -0.020673 0.0075244" quat="0.600789 0.372896 -0.600792 -0.372896">
        <inertial pos="0.0243414 -0.0048229 0.0170716" quat="0.79594 0.00867428 0.00295725 0.605306" mass="0.00170505" diaginertia="3.88055e-06 3.56509e-06 3.26048e-07"/>
        <joint name="J5R" pos="0 0 0" axis="0 0 1" damping="0.1"/>
        <geom class="collision" mesh="L3R"/>
        <geom class="visual" mesh="L3R"/>
        <geom class="aerodynamics" mesh="Proximal_R"/>
        <body name="L7R" pos="0.074121 -0.030565 -0.001" quat="0.932157 0 0 -0.362054">
          <inertial pos="0.0175244 -0.0044015 -0.00700329" quat="0.692947 -0.158508 -0.157599 0.685465" mass="0.00371107" diaginertia="1.27171e-05 1.00415e-05 2.72544e-06"/>
          <joint name="J6R" pos="-0.035 0 0.001" axis="0 0 1" damping="0.1"/>
          <geom class="collision" mesh="L7R"/>
          <geom class="visual" mesh="L7R"/>
          <geom class="aerodynamics" mesh="Distal_R"/>
        </body>
      </body>

      <site name="body_frame" pos="-0.015 0 0" quat="1 0 0 0"/>
      <site name="x_axis_b" type="box" pos=".1 .0 .0" size=".15 .005 .005" quat="1 0 0 0" rgba="1 0 0 0.2"/>
      <site name="y_axis_b" type="box" pos=".0 .1 .0" size=".15 .005 .005" quat=".707 0 0 .707" rgba="0 1 0 0.2"/>
      <site name="z_axis_b" type="box" pos=".0 .0 .1" size=".15 .005 .005" quat="-.707 0 .707 0" rgba="0 0 1 0.2"/>
    </body>
    <site name="x_axis" type="box" pos=".1 .0 .0" size=".15 .005 .005" quat="1 0 0 0" rgba="1 0 0 0.2"/>
    <site name="y_axis" type="box" pos=".0 .1 .0" size=".15 .005 .005" quat=".707 0 0 .707" rgba="0 1 0 0.2"/>
    <site name="z_axis" type="box" pos=".0 .0 .1" size=".15 .005 .005" quat="-.707 0 .707 0" rgba="0 0 1 0.2"/>
  </worldbody>

  <sensor>
    <framepos name="Body_pos" objtype="site" objname="body_frame"/>       <!-- datasensor[0:3] -->
    <framequat name="Body_quat" objtype="site" objname="body_frame"/>     <!-- datasensor[3:7] -->
    <framelinvel name="Body_linvel" objtype="site" objname="body_frame"/> <!-- datasensor[7:10] -->
    <gyro name="Body_angvel_local" site="body_frame"/>                    <!-- datasensor[10:13] -->
<!--    <frameangvel name="Body_angvel" objtype="site" objname="body_frame"/>-->
<!--    <velocimeter name="Body_linvel_local" site="body_frame"/>-->
  </sensor>

  <equality>
    <connect name = 'J4-eq' body1='L2'  body2='L3' anchor='0.035 0 0.001'/>
    <connect name = 'J8-eq' body1='Base'  body2='L5' anchor='0.0042 0.00929760 0.01993877'/>
    <connect name = 'J10-eq' body1='L6'  body2='L7' anchor='0.036 0 0'/>
    <connect name = 'J4R-eq' body1='L2R'  body2='L3R' anchor='0.035 0 0.001'/>
    <connect name = 'J8R-eq' body1='Base'  body2='L5R' anchor='-0.0032 -0.00929760 0.01993877'/>
    <connect name = 'J10R-eq' body1='L6R'  body2='L7R' anchor='0.036 0 0'/>
    <joint name = 'LeftRight' joint1='J1'  joint2='J1R' polycoef="0 1 0 0 0"/>
    <!-- <joint name = 'J1-eq' joint1='J1'  joint2='J1R' polycoef="0 1 0 0 0"/> -->
    <!-- <joint name = 'J2-eq' joint1='J2'  joint2='J2R' polycoef="0 1 0 0 0"/>
    <joint name = 'J3-eq' joint1='J2'  joint2='J3R' polycoef="0 1 0 0 0"/> -->
    <joint name = 'J5-eq' joint1='J5'  joint2='J5R' polycoef="0 1 0 0 0"/>
    <joint name = 'J6-eq' joint1='J6'  joint2='J6R' polycoef="0 1 0 0 0"/>
<!--    <joint name = 'J7-eq' joint1='J7'  joint2='J7R' polycoef="0 1 0 0 0"/>-->
<!--    <joint name = 'J9-eq' joint1='J9'  joint2='J9R' polycoef="0 1 0 0 0"/>-->
  </equality>

  <actuator>
    <velocity name="velocity_servo" joint="J1" ctrllimited="true" ctrlrange="-30 0" kv="3"/> (This is correct now) The "data.ctrl[0]" need set to -29.8451302
    <motor ctrllimited="true" ctrlrange="0 1" gear="0  0. 0.35 0. 0. -0.0056" site="motor1"/> unit: N
    <motor ctrllimited="true" ctrlrange="0 1" gear="0  0. 0.35 0. 0. -0.0056" site="motor2"/>
    <motor ctrllimited="true" ctrlrange="0 1" gear="0  0. 0.35 0. 0. -0.0056" site="motor3"/>
    <motor ctrllimited="true" ctrlrange="0 1" gear="0  0. 0.35 0. 0. -0.0056" site="motor4"/>
    <motor ctrllimited="true" ctrlrange="0 1" gear="0  0. .1 0. 0.  0.0016" site="motor5"/>
    <motor ctrllimited="true" ctrlrange="0 1" gear="0  0. -.1 0. 0. -0.0016" site="motor6"/>
  </actuator>

</mujoco>
